Workbook

Sheet MeltzerDiskret
A1: Mathematische Modellrechnungen zur Auswirkung einer Influenzapandemie in Deutschland
A2: Grundannahme Dauer der Pandemiewelle in Wochen | D2: 8
A3: Erkrankungsrate der Bevölkerung: 15 %, 30 %, 50 %, 70 %
A4: Landkreis Rhein-Sieg-Kreis | B4: =Parameter!B31
A6: Erkrankungsrate (ER) / 100.000 EW | B6: 0.15 | C6: 0.3 | D6: 0.5 | E6: 0.7
A7: Erkrankungen | B7: =100000*B6 | C7: =100000*C6 | D7: =100000*D6 | E7: =100000*E6
A8: Arztkonsultationen Spitzenbelastung /24h* | B8: =ROUND(B9/($D$2*7),0) | C8: =ROUND(C9/($D$2*7),0) | D8: =ROUND(D9/($D$2*7),0) | E8: =ROUND(E9/($D$2*7),0)
A9: Arztkonsultationen / Gesamt* | B9: =B7*Parameter!$B$3 | C9: =C7*Parameter!$B$3 | D9: =D7*Parameter!$B$3 | E9: =E7*Parameter!$B$3
A10: Hospitalisierungen Spitzenbelastung /24h* | B10: =ROUND(B11/($D$2*7),0) | C10: =ROUND(C11/($D$2*7),0) | D10: =ROUND(D11/($D$2*7),0) | E10: =ROUND(E11/($D$2*7),0)
A11: Hospitalisierungen (2,7%) / Gesamt* | B11: =ROUND(B9*Parameter!$B$4,0) | C11: =ROUND(C9*Parameter!$B$4,0) | D11: =ROUND(D9*Parameter!$B$4,0) | E11: =ROUND(E9*Parameter!$B$4,0)
A12: Tote Spitzenbelastung /24h* | B12: 1 | C12: 2 | D12: 3 | E12: 4
A13: Tote (0,7% d. Arztkonsultationen) / Gesamt* | B13: =ROUND(B9*Parameter!$B$5,0) | C13: =ROUND(C9*Parameter!$B$5,0) | D13: =ROUND(D9*Parameter!$B$5,0) | E13: =ROUND(E9*Parameter!$B$5,0)
A14: * Quelle: Modellrechnung Pandemieplan Land Hessen Februar 2007 (Seite 21 ff)
A16: Erkrankungsrate (ER) / Eigene Bevölkerung | B16: =B6 | C16: =C6 | D16: =D6 | E16: =E6
A17: Erkrankungen | B17: =ROUND($B$4*B16,0) | C17: =ROUND($B$4*C16,0) | D17: =ROUND($B$4*D16,0) | E17: =ROUND($B$4*E16,0)
A18: Arztkonsultationen Spitzenbelastung /24h* | B18: =ROUND(B19/($D$2*7),0) | C18: =ROUND(C19/($D$2*7),0) | D18: =ROUND(D19/($D$2*7),0) | E18: =ROUND(E19/($D$2*7),0)
A19: Arztkonsultationen / Gesamt* | B19: =ROUND(B17*Parameter!$B$3,0) | C19: =ROUND(C17*Parameter!$B$3,0) | D19: =ROUND(D17*Parameter!$B$3,0) | E19: =ROUND(E17*Parameter!$B$3,0)
A20: Hospitalisierungen Spitzenbelastung /24h | B20: =ROUND(B21/($D$2*7),0) | C20: =ROUND(C21/($D$2*7),0) | D20: =ROUND(D21/($D$2*7),0) | E20: =ROUND(E21/($D$2*7),0)
A21: Hospitalisierungen / Gesamt | B21: =ROUND(B19*Parameter!$B$4,0) | C21: =ROUND(C19*Parameter!$B$4,0) | D21: =ROUND(D19*Parameter!$B$4,0) | E21: =ROUND(E19*Parameter!$B$4,0)
A22: Krankenhausverlauf mild (80%) / Gesamt (nach RKI Steckbrief Coronavirus 2019) | B22: =ROUND(B17*0.8,0) | C22: =ROUND(C17*0.8,0) | D22: =ROUND(D17*0.8,0) | E22: =ROUND(E17*0.8,0)
A23: Krankenhausverlauf schwer (14%) / Gesamt (nach RKI Steckbrief Coronavirus 2019) | B23: =ROUND(B17*0.14,0) | C23: =ROUND(C17*0.14,0) | D23: =ROUND(D17*0.14,0) | E23: =ROUND(E17*0.14,0)
A24: Krankenhausverlauf kritisch (6%) / Gesamt (nach RKI Steckbrief Coronavirus 2019) | B24: =ROUND(B17*0.06,0) | C24: =ROUND(C17*0.06,0) | D24: =ROUND(D17*0.06,0) | E24: =ROUND(E17*0.06,0)
A25: Tote Spitzenbelastung /24h* | B25: =ROUND(B26/($D$2*7),0) | C25: =ROUND(C26/($D$2*7),0) | D25: =ROUND(D26/($D$2*7),0) | E25: =ROUND(E26/($D$2*7),0)
A26: Tote (0,7% d. Arztkonsultationen) / Gesamt* | B26: =ROUND(B19*Parameter!$B$5,0) | C26: =ROUND(C19*Parameter!$B$5,0) | D26: =ROUND(D19*Parameter!$B$5,0) | E26: =ROUND(E19*Parameter!$B$5,0)

Sheet MC-Simulation
A1: Mathematische Modellrechnungen zur Auswirkung einer Influenzapandemie in Deutschland
A2: Grundannahme Dauer der Pandemiewelle in Wochen | D2: 8
A3: =MeltzerDiskret!A4 | B3: =Parameter!B31
A5: Arztkonsultationen (Gesamt/ 100k EW) | B5: =MC_Metadata!B6 | F5: =A3
A6: Erkrankungsrate der Bevölkerung in Prozent | B6: min (q05) | C6: mode (q50) | D6: max (q95) | F6: =B6 | G6: =C6 | H6: =D6 | J6: Spannweite
A7: =MC_Quantile_100k!A2 | B7: =MC_Quantile_100k!B2 | C7: =MC_Quantile_100k!C2 | D7: =MC_Quantile_100k!D2 | F7: =ROUND(B7/100000*$B$3,0) | G7: =ROUND(C7/100000*$B$3,0) | H7: =ROUND(D7/100000*$B$3,0) | J7: =H7-F7
A8: =MC_Quantile_100k!A3 | B8: =MC_Quantile_100k!B3 | C8: =MC_Quantile_100k!C3 | D8: =MC_Quantile_100k!D3 | F8: =ROUND(B8/100000*$B$3,0) | G8: =ROUND(C8/100000*$B$3,0) | H8: =ROUND(D8/100000*$B$3,0) | J8: =H8-F8
A9: =MC_Quantile_100k!A4 | B9: =MC_Quantile_100k!B4 | C9: =MC_Quantile_100k!C4 | D9: =MC_Quantile_100k!D4 | F9: =ROUND(B9/100000*$B$3,0) | G9: =ROUND(C9/100000*$B$3,0) | H9: =ROUND(D9/100000*$B$3,0) | J9: =H9-F9
A10: =MC_Quantile_100k!A5 | B10: =MC_Quantile_100k!B5 | C10: =MC_Quantile_100k!C5 | D10: =MC_Quantile_100k!D5 | F10: =ROUND(B10/100000*$B$3,0) | G10: =ROUND(C10/100000*$B$3,0) | H10: =ROUND(D10/100000*$B$3,0) | J10: =H10-F10
A12: durchschn. Arztkonsultationen in 24 h/100k EW | B12: =B5 | F12: =F5
A13: Erkrankungsrate der Bevölkerung in Prozent | B13: min (q05) | C13: mode (q50) | D13: max (q95) | F13: =B13 | G13: =C13 | H13: =D13 | J13: =J6
A14: =MC_Quantile_100k!A2 | B14: =ROUND(B7/($D$2*7),0) | C14: =ROUND(C7/($D$2*7),0) | D14: =ROUND(D7/($D$2*7),0) | F14: =ROUND(B14/100000*$B$3,0) | G14: =ROUND(C14/100000*$B$3,0) | H14: =ROUND(D14/100000*$B$3,0) | J14: =H14-F14
A15: =MC_Quantile_100k!A3 | B15: =ROUND(B8/($D$2*7),0) | C15: =ROUND(C8/($D$2*7),0) | D15: =ROUND(D8/($D$2*7),0) | F15: =ROUND(B15/100000*$B$3,0) | G15: =ROUND(C15/100000*$B$3,0) | H15: =ROUND(D15/100000*$B$3,0) | J15: =H15-F15
A16: =MC_Quantile_100k!A4 | B16: =ROUND(B9/($D$2*7),0) | C16: =ROUND(C9/($D$2*7),0) | D16: =ROUND(D9/($D$2*7),0) | F16: =ROUND(B16/100000*$B$3,0) | G16: =ROUND(C16/100000*$B$3,0) | H16: =ROUND(D16/100000*$B$3,0) | J16: =H16-F16
A17: =MC_Quantile_100k!A5 | B17: =ROUND(B10/($D$2*7),0) | C17: =ROUND(C10/($D$2*7),0) | D17: =ROUND(D10/($D$2*7),0) | F17: =ROUND(B17/100000*$B$3,0) | G17: =ROUND(C17/100000*$B$3,0) | H17: =ROUND(D17/100000*$B$3,0) | J17: =H17-F17
A19: Hospitalisierungen (Gesamt/ 100k EW) | B19: =MC_Metadata!B7 | F19: =F5
A20: =A6 | B20: =B6 | C20: =C6 | D20: =D6 | F20: =F6 | G20: =G6 | H20: =H6 | J20: =J6
A21: =MC_Quantile_100k!A2 | B21: =MC_Quantile_100k!E2 | C21: =MC_Quantile_100k!F2 | D21: =MC_Quantile_100k!G2 | F21: =ROUND(B21/100000*$B$3,0) | G21: =ROUND(C21/100000*$B$3,0) | H21: =ROUND(D21/100000*$B$3,0) | J21: =H21-F21
A22: =MC_Quantile_100k!A3 | B22: =MC_Quantile_100k!E3 | C22: =MC_Quantile_100k!F3 | D22: =MC_Quantile_100k!G3 | F22: =ROUND(B22/100000*$B$3,0) | G22: =ROUND(C22/100000*$B$3,0) | H22: =ROUND(D22/100000*$B$3,0) | J22: =H22-F22
A23: =MC_Quantile_100k!A4 | B23: =MC_Quantile_100k!E4 | C23: =MC_Quantile_100k!F4 | D23: =MC_Quantile_100k!G4 | F23: =ROUND(B23/100000*$B$3,0) | G23: =ROUND(C23/100000*$B$3,0) | H23: =ROUND(D23/100000*$B$3,0) | J23: =H23-F23
A24: =MC_Quantile_100k!A5 | B24: =MC_Quantile_100k!E5 | C24: =MC_Quantile_100k!F5 | D24: =MC_Quantile_100k!G5 | F24: =ROUND(B24/100000*$B$3,0) | G24: =ROUND(C24/100000*$B$3,0) | H24: =ROUND(D24/100000*$B$3,0) | J24: =H24-F24
A26: durchschn. Hospitalisierungen in 24 h/1000k EW | B26: =MC_Metadata!B7 | F26: =F5
A27: =A6 | B27: =B6 | C27: =C6 | D27: =D6 | F27: =F6 | G27: =G6 | H27: =H6 | J27: =J6
A28: =MC_Quantile_100k!A2 | B28: =ROUND(B21/($D$2*7),0) | C28: =ROUND(C21/($D$2*7),0) | D28: =ROUND(D21/($D$2*7),0) | F28: =ROUND(B28/100000*$B$3,0) | G28: =ROUND(C28/100000*$B$3,0) | H28: =ROUND(D28/100000*$B$3,0) | J28: =H28-F28
A29: =MC_Quantile_100k!A3 | B29: =ROUND(B22/($D$2*7),0) | C29: =ROUND(C22/($D$2*7),0) | D29: =ROUND(D22/($D$2*7),0) | F29: =ROUND(B29/100000*$B$3,0) | G29: =ROUND(C29/100000*$B$3,0) | H29: =ROUND(D29/100000*$B$3,0) | J29: =H29-F29
A30: =MC_Quantile_100k!A4 | B30: =ROUND(B23/($D$2*7),0) | C30: =ROUND(C23/($D$2*7),0) | D30: =ROUND(D23/($D$2*7),0) | F30: =ROUND(B30/100000*$B$3,0) | G30: =ROUND(C30/100000*$B$3,0) | H30: =ROUND(D30/100000*$B$3,0) | J30: =H30-F30
A31: =MC_Quantile_100k!A5 | B31: =ROUND(B24/($D$2*7),0) | C31: =ROUND(C24/($D$2*7),0) | D31: =ROUND(D24/($D$2*7),0) | F31: =ROUND(B31/100000*$B$3,0) | G31: =ROUND(C31/100000*$B$3,0) | H31: =ROUND(D31/100000*$B$3,0) | J31: =H31-F31
A33: Tot (Gesamt/ 1000k EW) | B33: =MC_Metadata!B8 | F33: =F5
A34: =A6 | B34: =B6 | C34: =C6 | D34: =D6 | F34: =F6 | G34: =G6 | H34: =H6 | J34: =J6
A35: =MC_Quantile_100k!A2 | B35: =MC_Quantile_100k!H2 | C35: =MC_Quantile_100k!I2 | D35: =MC_Quantile_100k!J2 | F35: =ROUND(B35/100000*$B$3,0) | G35: =ROUND(C35/100000*$B$3,0) | H35: =ROUND(D35/100000*$B$3,0) | J35: =H35-F35
A36: =MC_Quantile_100k!A3 | B36: =MC_Quantile_100k!H3 | C36: =MC_Quantile_100k!I3 | D36: =MC_Quantile_100k!J3 | F36: =ROUND(B36/100000*$B$3,0) | G36: =ROUND(C36/100000*$B$3,0) | H36: =ROUND(D36/100000*$B$3,0) | J36: =H36-F36
A37: =MC_Quantile_100k!A4 | B37: =MC_Quantile_100k!H4 | C37: =MC_Quantile_100k!I4 | D37: =MC_Quantile_100k!J4 | F37: =ROUND(B37/100000*$B$3,0) | G37: =ROUND(C37/100000*$B$3,0) | H37: =ROUND(D37/100000*$B$3,0) | J37: =H37-F37
A38: =MC_Quantile_100k!A5 | B38: =MC_Quantile_100k!H5 | C38: =MC_Quantile_100k!I5 | D38: =MC_Quantile_100k!J5 | F38: =ROUND(B38/100000*$B$3,0) | G38: =ROUND(C38/100000*$B$3,0) | H38: =ROUND(D38/100000*$B$3,0) | J38: =H38-F38
A40: duchschn. Tote in 24h/1000k EW | B40: =MC_Metadata!B8 | F40: =F12
A41: =A13 | B41: =B13 | C41: =C13 | D41: =D13 | F41: =F13 | G41: =G13 | H41: =H13 | J41: =J13
A42: =MC_Quantile_100k!A2 | B42: =ROUND(B35/($D$2*7),0) | C42: =ROUND(C35/($D$2*7),0) | D42: =ROUND(D35/($D$2*7),0) | F42: =ROUND(B42/100000*$B$3,0) | G42: =ROUND(C42/100000*$B$3,0) | H42: =ROUND(D42/100000*$B$3,0) | J42: =H42-F42
A43: =MC_Quantile_100k!A3 | B43: =ROUND(B36/($D$2*7),0) | C43: =ROUND(C36/($D$2*7),0) | D43: =ROUND(D36/($D$2*7),0) | F43: =ROUND(B43/100000*$B$3,0) | G43: =ROUND(C43/100000*$B$3,0) | H43: =ROUND(D43/100000*$B$3,0) | J43: =H43-F43
A44: =MC_Quantile_100k!A4 | B44: =ROUND(B37/($D$2*7),0) | C44: =ROUND(C37/($D$2*7),0) | D44: =ROUND(D37/($D$2*7),0) | F44: =ROUND(B44/100000*$B$3,0) | G44: =ROUND(C44/100000*$B$3,0) | H44: =ROUND(D44/100000*$B$3,0) | J44: =H44-F44
A45: =MC_Quantile_100k!A5 | B45: =ROUND(B38/($D$2*7),0) | C45: =ROUND(C38/($D$2*7),0) | D45: =ROUND(D38/($D$2*7),0) | F45: =ROUND(B45/100000*$B$3,0) | G45: =ROUND(C45/100000*$B$3,0) | H45: =ROUND(D45/100000*$B$3,0) | J45: =H45-F45
A75: Erkrankungen | B75: =100000*B45 | C75: =100000*C45 | D75: =100000*D45 | E75: =100000*E45
...

Sheet Parameter
A3: Arztkonsukltationen (Rate) | B3: 0.5
A4: Hospitalisierungsrate pro Konsultation | B4: 0.027
A5: Todesrate pro Konsultation | B5: 0.007
A10: Gemeinde | B10: Einwohner
A11: Troisdorf | B11: 75901
A12: Sankt Augustin | B12: 56521
A13: Bornheim | B13: 48203
A14: Hennef (Sieg) | B14: 48188
A15: Siegburg | B15: 42445
A16: Königswinter | B16: 40574
A17: Niederkassel | B17: 38485
A18: Lohmar | B18: 30992
A19: Rheinbach | B19: 26918
A20: Bad Honnef | B20: 25061
A21: Meckenheim | B21: 24925
A22: Alfter | B22: 23719
... A29: Ruppichteroth | B29: 10887
A31: Gesamt | B31: =SUM(B11:B29)

Sheet MC_Quantile_100k
A1: Erkrankungsrate_% | B1: consult_total_q05 | C1: consult_total_q50 | D1: consult_total_q95 | E1: hosp_total_q05 | F1: hosp_total_q50 | G1: hosp_total_q95 | H1: deaths_total_q05 | I1: deaths_total_q50 | J1: deaths_total_q95
A2: 15 | B2: 6988 | C2: 7500 | D2: 8013 | E2: 182 | F2: 202 | G2: 223 | H2: 37 | I2: 52 | J2: 68
A3: 30 | B3: 13974 | C3: 15001 | D3: 16025 | E3: 365 | F3: 405 | G3: 447 | H3: 74 | I3: 105 | J3: 137
A4: 50 | B4: 23294 | C4: 25000 | D4: 26710 | E4: 609 | F4: 674 | G4: 744 | H4: 123 | I4: 175 | J4: 228
A5: 70 | B5: 32606 | C5: 35002 | D5: 37394 | E5: 852 | F5: 944 | G5: 1042 | H5: 172 | I5: 245 | J5: 319

Sheet MC_Metadata
A1: Schlüssel | B1: Wert
A2: Modell | B2: Meltzer (vereinfachtes Kettenmodell)
A3: Simulationstyp | B3: Monte-Carlo
A4: Stichprobengröße n | B4: 200.000
A5: Zufallsverteilungen | B5: Dreiecksverteilungen
A6: consult_frac | B6: min=0,45 · mode=0,5 · max=0,55
A7: hosp_per_consult | B7: min=0,024 · mode=0,027 · max=0,03
A8: death_per_consult | B8: min=0,004 · mode=0,007 · max=0,01
A9: Erkrankungsraten | B9: 15 %, 30 %, 50 %, 70 %
A10: Normierung | B10: pro 100.000 Einwohner
A11: Rundung | B11: intern reell, Darstellung gerundet
A12: Zufallsseed | B12: 42
A13: Erstellungsdatum | B13: 2026-01-07
